Workbook
Name Cod_proy: #REF!
Name Cod_proy: #REF!
Name Giro_Alpin: #REF!
Name Giro_Alpin: #REF!
Name Lider_Nombre: #REF!
Name Lider_Nombre: #REF!
Name Nivel: #REF!
Name Nivel: #REF!
Name Nom_Cl: #REF!
Name Nom_Cl: #REF!
Name tblDatos: OFFSET(#REF!,0,0,COUNTA(#REF!),11)
Name tblDatos: OFFSET(#REF!,0,0,COUNTA(#REF!),11)

Sheet ENERO
C1: CALCULO DE BONOS ENERO
C3: REGION OCCIDENTE
C5: KILOS | E5: Variacion | G5: PESOS | I5: Variacion
B6: MES | C6: Presupuesto | D6: Real | E6: KG | F6: % | G6: Presupuesto | H6: Real | I6: $ | J6: %
B7: ENERO | C7: 143666.11 | D7: 176493.95 | E7: =D7-C7 -> 32827.834 | F7: =D7/C7-1 -> 0.22850088 | G7: 4297825.1 | H7: 4667283 | I7: =H7-G7 -> 369457.84 | J7: =H7/G7-1 -> 0.085963907
B9: COMPOSICION BONO | G9: ALCANCE DE OBJETIVOS
B10: Bono | C10: Concepto | D10: % Bono | E10: Monto | G10: Concepto | H10: Presupuesto | I10: Real | J10: % Cobertura | K10: Bono | M10: Objetivo Minimo
B11: 12000 | C11: Cumplimiento Presupuesto | D11: 0.7 | E11: =B11*D11 -> 8400 | G11: Cumplimiento Presupuesto | H11: =G7 -> 4297825.1 | I11: =H7 -> 4667283 | J11: =IFERROR(I11/H11,0) -> 1.0859639 | K11: =IF(J11<M11,0,J11*$E11) -> 9122.0968 | M11: 0.9
C12: Cierre de 3 pedidos 1000 Kgcon clientes actuales de FMC | D12: 0.12 | E12: =B11*D12 -> 1440 | G12: =C12 -> Cierre de 3 pedidos 1000 Kgcon clientes actuales de FMC | H12: 1 | J12: =I12/H12 -> 0 | K12: =IF(J12<M12,0,J12*$E12) -> 0 | M12: 0.8
C13: Contar con calendario de pruebas inicios de año 2020 | D13: 0.05 | E13: =B$11*D$13 -> 600 | G13: =C13 -> Contar con calendario de pruebas inicios de año 2020 | H13: 1 | J13: =I13/H13 -> 0 | K13: =IF(J13<M13,0,J13*$E13) -> 0 | M13: 1
C14: Presentar estrategica por region Occidente 2020 | D14: 0.05 | E14: =B$11*D$13 -> 600 | G14: =C14 -> Presentar estrategica por region Occidente 2020 | H14: 1 | J14: =I14/H14 -> 0 | K14: =IF(J14<M14,0,J14*$E14) -> 0 | M14: 0.75
C15: Presentar presupuesto lunes 6 de Diciembre | D15: 0.08 | E15: =B11*D15 -> 960 | G15: =C15 -> Presentar presupuesto lunes 6 de Diciembre | H15: 1 | J15: =I15/H15 -> 0 | K15: =IF(J15<M15,0,J15*$E15) -> 0 | M15: 0.75
C16: Total | D16: =SUM(D11:D15) -> 1 | E16: =SUM(E11:E15) -> 12000 | J16: Total sin Presupuesto | K16: =SUM(K12:K15) -> 0
J18: TOTAL | K18: =+K16+K11 -> 9122.0968
C24: REGION PACIFICO
C26: KILOS | E26: Variacion | G26: PESOS | I26: Variacion
B27: MES | C27: Presupuesto | D27: Real | E27: KG | F27: % | G27: Presupuesto | H27: Real | I27: $ | J27: %
B28: =$B$7 -> ENERO | C28: 38799 | D28: 24322.564 | E28: =D28-C28 -> -14476.436 | F28: =D28/C28-1 -> -0.37311364 | G28: 2453010.1 | H28: 1240760.1 | I28: =H28-G28 -> -1212249.9 | J28: =H28/G28-1 -> -0.49418873
B30: COMPOSICION BONO
B31: Bono | C31: Concepto | D31: % Bono | E31: Monto | F31: Objetivo Minimo | G31: Concepto | H31: Presupuesto | I31: Real | J31: % Cobertura | K31: Bono | M31: Objetivo Minimo
B32: 1000 | C32: Cumplimiento Presupuesto | D32: =E32/$B$37 -> 0.15384615 | E32: 1000 | F32: 0.5 | G32: =C32 -> Cumplimiento Presupuesto | H32: =G28 -> 2453010.1 | I32: =H28 -> 1240760.1 | J32: =IFERROR(I32/H32,0) -> 0.50581127 | K32: =IF(J32<M32,0,J32*$E32) -> 505.81127 | M32: 0.5
B33: 1000 | C33: Pruebas atorizadas por realizar con cliente | D33: =E33/$B$37 -> 0.15384615 | E33: 1000 | F33: 1 | G33: =C33 -> Pruebas atorizadas por realizar con cliente | H33: 1 | J33: =IFERROR(I33/H33,0) -> 0 | K33: =IF(J33<M33,0,J33*$E33) -> 0 | M33: 1
B34: 1500 | C34: Armado e implementación estrategia Baja California | D34: =E34/$B$37 -> 0.23076923 | E34: 1500 | F34: 1 | G34: =C34 -> Armado e implementación estrategia Baja California | H34: 1 | J34: =IFERROR(I34/H34,0) -> 0 | K34: =IF(J34<M34,0,J34*$E34) -> 0 | M34: 1
B35: 1500 | C35: Presentar estrategica por región 2020 | D35: =E35/$B$37 -> 0.23076923 | E35: 1500 | F35: 0.75 | G35: =C35 -> Presentar estrategica por región 2020 | H35: 1 | J35: =IFERROR(I35/H35,0) -> 0 | K35: =IF(J35<M35,0,J35*$E35) -> 0 | M35: 0.75
B36: 1500 | C36: Presentar presupuesto lunes 6 de Diciembre | D36: =E36/$B$37 -> 0.23076923 | E36: 1500 | F36: 0.75 | G36: =C36 -> Presentar presupuesto lunes 6 de Diciembre | H36: 1 | J36: =IFERROR(I36/H36,0) -> 0 | K36: =IF(J36<M36,0,J36*$E36) -> 0 | M36: 0.75
B37: =SUM(B32:B36) -> 6500 | C37: Total | E37: =SUM(E31:E36) -> 6500 | J37: Total sin Presupuesto | K37: =SUM(K34:K34) -> 0
J39: TOTAL | K39: =+K37+K32 -> 505.81127
J40: Abono adeudo Marinador
J41: Total a pagar | K41: =+K39-K40 -> 505.81127
C43: REGION BAJIO
C45: KILOS | E45: Variacion | G45: PESOS | I45: Variacion
B46: MES | C46: Presupuesto | D46: Real | E46: KG | F46: % | G46: Presupuesto | H46: Real | I46: $ | J46: %
B47: =$B$7 -> ENERO | C47: 22303.184 | D47: 29864.766 | E47: =D47-C47 -> 7561.5817 | F47: =D47/C47-1 -> 0.33903597 | G47: 1364911.6 | H47: 1383531 | I47: =H47-G47 -> 18619.354 | J47: =H47/G47-1 -> 0.013641435
B49: COMPOSICION BONO | G49: ALCANCE DE OBJETIVOS
B50: Bono | C50: Concepto | D50: % Bono | E50: Monto | G50: Concepto | H50: Presupuesto | I50: Real | J50: % Cobertura | K50: Bono
B51: 7000 | C51: Cumplimiento Presupuesto | D51: 0.5 | E51: =B51*D51 -> 3500 | G51: =C51 -> Cumplimiento Presupuesto | H51: =G47 -> 1364911.6 | I51: =H47 -> 1383531 | J51: =IFERROR(I51/H51,0) -> 1.0136414 | K51: =IF(J51<M52,0,J51*$E51) -> 3547.745 | M51: Objetivo Minimo
C52: Aplicación de pruebas unidades de chorizo | D52: 0.2 | E52: =B51*D52 -> 1400 | G52: =C52 -> Aplicación de pruebas unidades de chorizo | H52: 1 | J52: =IFERROR(I52/H52,0) -> 0 | K52: =IF(J52<M53,0,J52*$E52) -> 0 | M52: 0.95
C53: Prospectación | D53: 0.2 | E53: =B51*D53 -> 1400 | G53: =C53 -> Prospectación | H53: 1 | J53: =IFERROR(I53/H53,0) -> 0 | K53: =IF(J53<M54,0,J53*$E53) -> 0 | M53: 0.75
C54: Cierre de venta con productos nuevos AGR | D54: 0.1 | E54: =+D54*B51 -> 700 | G54: =C54 -> Cierre de venta con productos nuevos AGR | H54: 1 | J54: =IFERROR(I54/H54,0) -> 0 | K54: =IF(J54<M55,0,J54*$E54) -> 0 | M54: 0.75
C55: Total | D55: =SUM(D51:D54) -> 1 | E55: =SUM(E51:E54) -> 7000 | J55: Total sin Presupuesto | K55: =SUM(K52:K54) -> 0 | M55: 0.75
...

Sheet FEBRERO
C1: CALCULO DE BONOS FEBRERO
C3: REGION OCCIDENTE
C5: KILOS | E5: Variacion | G5: PESOS | I5: Variacion
B6: MES | C6: Presupuesto | D6: Real | E6: KG | F6: % | G6: Presupuesto | H6: Real | I6: $ | J6: %
B7: FEBRERO | C7: ='ESSENTIA FEB'!O27 -> 149031.37 | D7: ='ESSENTIA FEB'!N27 -> 134310.4 | E7: =D7-C7 -> -14720.97 | F7: =D7/C7-1 -> -0.098777655 | G7: ='ESSENTIA FEB'!G27 -> 4256404.4 | H7: ='ESSENTIA FEB'!F27 -> 3799747.9 | I7: =H7-G7 -> -456656.47 | J7: =H7/G7-1 -> -0.10728691
B9: COMPOSICION BONO | G9: ALCANCE DE OBJETIVOS
B10: Bono | C10: Concepto | D10: % Bono | E10: Monto | G10: Concepto | H10: Presupuesto | I10: Real | J10: % Cobertura | K10: Bono | M10: Objetivo Minimo
B11: 12000 | C11: Cumplimiento Presupuesto | D11: 0.7 | E11: =B11*D11 -> 8400 | G11: Cumplimiento Presupuesto | H11: =G7 -> 4256404.4 | I11: =H7 -> 3799747.9 | J11: =IFERROR(I11/H11,0) -> 0.89271309 | K11: =IF(J11<M11,0,J11*$E11) -> 0 | M11: 0.9
C12: Cierre de 3 pedidos 1000 Kgcon clientes actuales de FMC | D12: 0.12 | E12: =B11*D12 -> 1440 | G12: =C12 -> Cierre de 3 pedidos 1000 Kgcon clientes actuales de FMC | H12: 1 | J12: =I12/H12 -> 0 | K12: =IF(J12<M12,0,J12*$E12) -> 0 | M12: 0.8
C13: Contar con calendario de pruebas inicios de año 2020 | D13: 0.05 | E13: =B$11*D$13 -> 600 | G13: =C13 -> Contar con calendario de pruebas inicios de año 2020 | H13: 1 | J13: =I13/H13 -> 0 | K13: =IF(J13<M13,0,J13*$E13) -> 0 | M13: 1
C14: Presentar estrategica por region Occidente 2020 | D14: 0.05 | E14: =B$11*D$13 -> 600 | G14: =C14 -> Presentar estrategica por region Occidente 2020 | H14: 1 | J14: =I14/H14 -> 0 | K14: =IF(J14<M14,0,J14*$E14) -> 0 | M14: 0.75
C15: Presentar presupuesto lunes 6 de Diciembre | D15: 0.08 | E15: =B11*D15 -> 960 | G15: =C15 -> Presentar presupuesto lunes 6 de Diciembre | H15: 1 | J15: =I15/H15 -> 0 | K15: =IF(J15<M15,0,J15*$E15) -> 0 | M15: 0.75
C16: Total | D16: =SUM(D11:D15) -> 1 | E16: =SUM(E11:E15) -> 12000 | J16: Total sin Presupuesto | K16: =SUM(K12:K15) -> 0
J18: TOTAL | K18: =+K16+K11 -> 0
C24: REGION PACIFICO
C26: KILOS | E26: Variacion | G26: PESOS | I26: Variacion
B27: MES | C27: Presupuesto | D27: Real | E27: KG | F27: % | G27: Presupuesto | H27: Real | I27: $ | J27: %
B28: =$B$7 -> FEBRERO | C28: ='ESSENTIA FEB'!O28 -> 34839 | D28: ='ESSENTIA FEB'!N28 -> 29580.708 | E28: =D28-C28 -> -5258.2921 | F28: =D28/C28-1 -> -0.1509312 | G28: ='ESSENTIA FEB'!G28 -> 2205545.3 | H28: ='ESSENTIA FEB'!F28 -> 2144834.8 | I28: =H28-G28 -> -60710.488 | J28: =H28/G28-1 -> -0.027526294
B30: COMPOSICION BONO
B31: Bono | C31: Concepto | D31: % Bono | E31: Monto | F31: Objetivo Minimo | G31: Concepto | H31: Presupuesto | I31: Real | J31: % Cobertura | K31: Bono | M31: Objetivo Minimo
B32: 1000 | C32: Cumplimiento Presupuesto | D32: =E32/$B$37 -> 0.15384615 | E32: 1000 | F32: 0.5 | G32: =C32 -> Cumplimiento Presupuesto | H32: =G28 -> 2205545.3 | I32: =H28 -> 2144834.8 | J32: =IFERROR(I32/H32,0) -> 0.97247371 | K32: =IF(J32<M32,0,J32*$E32) -> 972.47371 | M32: 0.5
B33: 1000 | C33: Pruebas atorizadas por realizar con cliente | D33: =E33/$B$37 -> 0.15384615 | E33: 1000 | F33: 1 | G33: =C33 -> Pruebas atorizadas por realizar con cliente | H33: 1 | J33: =IFERROR(I33/H33,0) -> 0 | K33: =IF(J33<M33,0,J33*$E33) -> 0 | M33: 1
B34: 1500 | C34: Armado e implementación estrategia Baja California | D34: =E34/$B$37 -> 0.23076923 | E34: 1500 | F34: 1 | G34: =C34 -> Armado e implementación estrategia Baja California | H34: 1 | J34: =IFERROR(I34/H34,0) -> 0 | K34: =IF(J34<M34,0,J34*$E34) -> 0 | M34: 1
B35: 1500 | C35: Presentar estrategica por región 2020 | D35: =E35/$B$37 -> 0.23076923 | E35: 1500 | F35: 0.75 | G35: =C35 -> Presentar estrategica por región 2020 | H35: 1 | J35: =IFERROR(I35/H35,0) -> 0 | K35: =IF(J35<M35,0,J35*$E35) -> 0 | M35: 0.75
B36: 1500 | C36: Presentar presupuesto lunes 6 de Diciembre | D36: =E36/$B$37 -> 0.23076923 | E36: 1500 | F36: 0.75 | G36: =C36 -> Presentar presupuesto lunes 6 de Diciembre | H36: 1 | J36: =IFERROR(I36/H36,0) -> 0 | K36: =IF(J36<M36,0,J36*$E36) -> 0 | M36: 0.75
B37: =SUM(B32:B36) -> 6500 | C37: Total | E37: =SUM(E31:E36) -> 6500 | J37: Total sin Presupuesto | K37: =SUM(K34:K34) -> 0
J39: TOTAL | K39: =+K37+K32 -> 972.47371
C43: REGION BAJIO
C45: KILOS | E45: Variacion | G45: PESOS | I45: Variacion
B46: MES | C46: Presupuesto | D46: Real | E46: KG | F46: % | G46: Presupuesto | H46: Real | I46: $ | J46: %
B47: =$B$7 -> FEBRERO | C47: ='ESSENTIA FEB'!O32 -> 24032.929 | D47: ='ESSENTIA FEB'!N32 -> 27953.524 | E47: =D47-C47 -> 3920.5948 | F47: =D47/C47-1 -> 0.16313429 | G47: ='ESSENTIA FEB'!G32 -> 1288812.4 | H47: ='ESSENTIA FEB'!F32 -> 1575484.4 | I47: =H47-G47 -> 286672.1 | J47: =H47/G47-1 -> 0.22243122
B49: COMPOSICION BONO | G49: ALCANCE DE OBJETIVOS
B50: Bono | C50: Concepto | D50: % Bono | E50: Monto | G50: Concepto | H50: Presupuesto | I50: Real | J50: % Cobertura | K50: Bono
B51: 7000 | C51: Cumplimiento Presupuesto | D51: 0.5 | E51: =B51*D51 -> 3500 | G51: =C51 -> Cumplimiento Presupuesto | H51: =G47 -> 1288812.4 | I51: =H47 -> 1575484.4 | J51: =IFERROR(I51/H51,0) -> 1.2224312 | K51: =IF(J51<M52,0,J51*$E51) -> 4278.5093 | M51: Objetivo Minimo
C52: Aplicación de pruebas unidades de chorizo | D52: 0.2 | E52: =B51*D52 -> 1400 | G52: =C52 -> Aplicación de pruebas unidades de chorizo | H52: 1 | J52: =IFERROR(I52/H52,0) -> 0 | K52: =IF(J52<M53,0,J52*$E52) -> 0 | M52: 0.95
C53: Prospectación | D53: 0.2 | E53: =B51*D53 -> 1400 | G53: =C53 -> Prospectación | H53: 1 | J53: =IFERROR(I53/H53,0) -> 0 | K53: =IF(J53<M54,0,J53*$E53) -> 0 | M53: 0.75
C54: Cierre de venta con productos nuevos AGR | D54: 0.1 | E54: =+D54*B51 -> 700 | G54: =C54 -> Cierre de venta con productos nuevos AGR | H54: 1 | J54: =IFERROR(I54/H54,0) -> 0 | K54: =IF(J54<M55,0,J54*$E54) -> 0 | M54: 0.75
C55: Total | D55: =SUM(D51:D54) -> 1 | E55: =SUM(E51:E54) -> 7000 | J55: Total sin Presupuesto | K55: =SUM(K52:K54) -> 0 | M55: 0.75
J57: TOTAL | K57: =+K55+K51 -> 4278.5093
C61: ALTOS NORTE
...

Sheet ESSENTIA FEB
E3: PRESUPUESTO ORIGINAL | F3: Importes | N3: Kilogramos
D4: Clave | E4: Region | F4: 2020 | G4: Pres | H4: Dif | I4: % Inc | J4: 2019 | K4: Dif | L4: % Inc | N4: 2020 | O4: Pres | P4: Dif | Q4: % Inc | R4: 2019 | S4: Dif | T4: % Inc
D5: 1 | E5: Occidente | F5: 3799747.9 | G5: 4354552.4 | H5: =F5-G5 -> -554804.51 | I5: =IFERROR(F5/G5-1,0) -> -0.12740793 | J5: 5433696.7 | K5: =F5-J5 -> -1633948.8 | L5: =IFERROR(F5/J5-1,0) -> -0.30070666 | N5: 134310.4 | O5: 149514.37 | P5: =N5-O5 -> -15203.97 | Q5: =IFERROR(N5/O5-1,0) -> -0.10168902 | R5: 169472.67 | S5: =N5-R5 -> -35162.266 | T5: =IFERROR(N5/R5-1,0) -> -0.20748045
D6: 2 | E6: Pacifico | F6: 2144834.8 | G6: 2211391.5 | H6: =F6-G6 -> -66556.678 | I6: =IFERROR(F6/G6-1,0) -> -0.030097193 | J6: 4367621 | K6: =F6-J6 -> -2222786.1 | L6: =IFERROR(F6/J6-1,0) -> -0.50892377 | N6: 29580.708 | O6: 34859 | P6: =N6-O6 -> -5278.2921 | Q6: =IFERROR(N6/O6-1,0) -> -0.15141835 | R6: 81065.497 | S6: =N6-R6 -> -51484.789 | T6: =IFERROR(N6/R6-1,0) -> -0.63510113
D7: 3 | E7: Servicio al cliente | F7: 1586907 | G7: 2163659.5 | H7: =F7-G7 -> -576752.48 | I7: =IFERROR(F7/G7-1,0) -> -0.26656343 | J7: 1522760.3 | K7: =F7-J7 -> 64146.7 | L7: =IFERROR(F7/J7-1,0) -> 0.042125278 | N7: 49576.13 | O7: 71475.08 | P7: =N7-O7 -> -21898.95 | Q7: =IFERROR(N7/O7-1,0) -> -0.30638581 | R7: 47484.45 | S7: =N7-R7 -> 2091.6803 | T7: =IFERROR(N7/R7-1,0) -> 0.044049796
D8: 5 | E8: Mexico | F8: 121042.57 | G8: 114742.17 | H8: =F8-G8 -> 6300.397 | I8: =IFERROR(F8/G8-1,0) -> 0.054909166 | J8: 134134.86 | K8: =F8-J8 -> -13092.29 | L8: =IFERROR(F8/J8-1,0) -> -0.097605425 | N8: 150 | O8: 130 | P8: =N8-O8 -> 20 | Q8: =IFERROR(N8/O8-1,0) -> 0.15384615 | R8: 160 | S8: =N8-R8 -> -10 | T8: =IFERROR(N8/R8-1,0) -> -0.0625
D9: 6 | E9: Altos Norte | F9: 2450819.7 | G9: 2431461.7 | H9: =F9-G9 -> 19358.026 | I9: =IFERROR(F9/G9-1,0) -> 0.007961477 | J9: 2822915.1 | K9: =F9-J9 -> -372095.36 | L9: =IFERROR(F9/J9-1,0) -> -0.13181245 | N9: 71398.03 | O9: 92726.672 | P9: =N9-O9 -> -21328.642 | Q9: =IFERROR(N9/O9-1,0) -> -0.23001626 | R9: 96533.346 | S9: =N9-R9 -> -25135.316 | T9: =IFERROR(N9/R9-1,0) -> -0.26037962
D10: 7 | E10: Bajio | F10: 1575484.4 | G10: 1300918.2 | H10: =F10-G10 -> 274566.21 | I10: =IFERROR(F10/G10-1,0) -> 0.2110557 | J10: 1228581.4 | K10: =F10-J10 -> 346903.07 | L10: =IFERROR(F10/J10-1,0) -> 0.28236068 | N10: 27953.524 | O10: 24074.929 | P10: =N10-O10 -> 3878.5948 | Q10: =IFERROR(N10/O10-1,0) -> 0.16110514 | R10: 22928.504 | S10: =N10-R10 -> 5025.02 | T10: =IFERROR(N10/R10-1,0) -> 0.2191604
F11: =SUM(F5:F10) -> 11678836 | G11: =SUM(G5:G10) -> 12576726 | H11: =F11-G11 -> -897889.04 | I11: =IFERROR(F11/G11-1,0) -> -0.071392911 | J11: =SUM(J5:J10) -> 15509709 | K11: =F11-J11 -> -3830872.8 | L11: =IFERROR(F11/J11-1,0) -> -0.24699836 | N11: =SUM(N5:N10) -> 312968.8 | O11: =SUM(O5:O10) -> 372780.05 | P11: =N11-O11 -> -59811.259 | Q11: =IFERROR(N11/O11-1,0) -> -0.16044651 | R11: =SUM(R5:R10) -> 417644.47 | S11: =N11-R11 -> -104675.67 | T11: =IFERROR(N11/R11-1,0) -> -0.25063344
E14: PERDIDA VENTA ESSENTIA | F14: Importes | N14: Kilogramos
D15: Clave | E15: Region | F15: 2020 | G15: Pres | H15: Dif | I15: % Inc | J15: 2019 | K15: Dif | L15: % Inc | N15: 2020 | O15: Pres | P15: Dif | Q15: % Inc | R15: 2019 | S15: Dif | T15: % Inc
D16: 1 | E16: Occidente | G16: =L40+L41+L42+L43+L44+L45+L46+L47 -> -98148.039 | O16: =H40+H41+H42+H43+H44+H45+H46+H47 -> -483
D17: 2 | E17: Pacifico | G17: =L58 -> -5846.19 | O17: =H58 -> -20
D18: 3 | E18: Servicio al cliente | G18: =L66+L67+L68+L69+L70+L71 -> -31389.151 | O18: =H66+H67+H68+H69+H70+H71 -> -132
D19: 5 | E19: Mexico
D20: 6 | E20: Altos Norte | G20: =L80+L81+L82+L83+L84+L85+L86 -> -70421.879 | O20: =H80+H81+H82+H83+H84+H85 -> -317
D21: 7 | E21: Bajio | G21: =L95 -> -12105.891 | O21: =H95 -> -42
F22: =SUM(F16:F21) -> 0 | G22: =SUM(G16:G21) -> -217911.15 | H22: =F22-G22 -> 217911.15 | I22: =IFERROR(F22/G22-1,0) -> -1 | J22: =SUM(J16:J21) -> 0 | K22: =F22-J22 -> 0 | L22: =IFERROR(F22/J22-1,0) -> 0 | N22: =SUM(N16:N21) -> 0 | O22: =SUM(O16:O21) -> -994 | P22: =N22-O22 -> 994 | Q22: =IFERROR(N22/O22-1,0) -> -1 | R22: =SUM(R16:R21) -> 0 | S22: =N22-R22 -> 0 | T22: =IFERROR(N22/R22-1,0) -> 0
E25: PRESUPUESTO MODIFICADO | F25: Importes | N25: Kilogramos
D26: Clave | E26: Region | F26: 2020 | G26: Pres | H26: Dif | I26: % Inc | J26: 2019 | K26: Dif | L26: % Inc | N26: 2020 | O26: Pres | P26: Dif | Q26: % Inc | R26: 2019 | S26: Dif | T26: % Inc
D27: 1 | E27: Occidente | F27: 3799747.9 | G27: =G5+G16 -> 4256404.4 | H27: =F27-G27 -> -456656.47 | I27: =IFERROR(F27/G27-1,0) -> -0.10728691 | J27: 5433696.7 | K27: =F27-J27 -> -1633948.8 | L27: =IFERROR(F27/J27-1,0) -> -0.30070666 | N27: 134310.4 | O27: =O5+O16 -> 149031.37 | P27: =N27-O27 -> -14720.97 | Q27: =IFERROR(N27/O27-1,0) -> -0.098777655 | R27: 169472.67 | S27: =N27-R27 -> -35162.266 | T27: =IFERROR(N27/R27-1,0) -> -0.20748045
D28: 2 | E28: Pacifico | F28: 2144834.8 | G28: =G6+G17 -> 2205545.3 | H28: =F28-G28 -> -60710.488 | I28: =IFERROR(F28/G28-1,0) -> -0.027526294 | J28: 4367621 | K28: =F28-J28 -> -2222786.1 | L28: =IFERROR(F28/J28-1,0) -> -0.50892377 | N28: 29580.708 | O28: =O6+O17 -> 34839 | P28: =N28-O28 -> -5258.2921 | Q28: =IFERROR(N28/O28-1,0) -> -0.1509312 | R28: 81065.497 | S28: =N28-R28 -> -51484.789 | T28: =IFERROR(N28/R28-1,0) -> -0.63510113
D29: 3 | E29: Servicio al cliente | F29: 1586907 | G29: =G7+G18 -> 2132270.3 | H29: =F29-G29 -> -545363.33 | I29: =IFERROR(F29/G29-1,0) -> -0.25576651 | J29: 1522760.3 | K29: =F29-J29 -> 64146.7 | L29: =IFERROR(F29/J29-1,0) -> 0.042125278 | N29: 49576.13 | O29: =O7+O18 -> 71343.08 | P29: =N29-O29 -> -21766.95 | Q29: =IFERROR(N29/O29-1,0) -> -0.30510247 | R29: 47484.45 | S29: =N29-R29 -> 2091.6803 | T29: =IFERROR(N29/R29-1,0) -> 0.044049796
D30: 5 | E30: Mexico | F30: 121042.57 | G30: =G8+G19 -> 114742.17 | H30: =F30-G30 -> 6300.397 | I30: =IFERROR(F30/G30-1,0) -> 0.054909166 | J30: 134134.86 | K30: =F30-J30 -> -13092.29 | L30: =IFERROR(F30/J30-1,0) -> -0.097605425 | N30: 150 | O30: =O8+O19 -> 130 | P30: =N30-O30 -> 20 | Q30: =IFERROR(N30/O30-1,0) -> 0.15384615 | R30: 160 | S30: =N30-R30 -> -10 | T30: =IFERROR(N30/R30-1,0) -> -0.0625
D31: 6 | E31: Altos Norte | F31: 2450819.7 | G31: =G9+G20 -> 2361039.8 | H31: =F31-G31 -> 89779.906 | I31: =IFERROR(F31/G31-1,0) -> 0.038025579 | J31: 2822915.1 | K31: =F31-J31 -> -372095.36 | L31: =IFERROR(F31/J31-1,0) -> -0.13181245 | N31: 71398.03 | O31: =O9+O20 -> 92409.672 | P31: =N31-O31 -> -21011.642 | Q31: =IFERROR(N31/O31-1,0) -> -0.22737492 | R31: 96533.346 | S31: =N31-R31 -> -25135.316 | T31: =IFERROR(N31/R31-1,0) -> -0.26037962
D32: 7 | E32: Bajio | F32: 1575484.4 | G32: =G10+G21 -> 1288812.4 | H32: =F32-G32 -> 286672.1 | I32: =IFERROR(F32/G32-1,0) -> 0.22243122 | J32: 1228581.4 | K32: =F32-J32 -> 346903.07 | L32: =IFERROR(F32/J32-1,0) -> 0.28236068 | N32: 27953.524 | O32: =O10+O21 -> 24032.929 | P32: =N32-O32 -> 3920.5948 | Q32: =IFERROR(N32/O32-1,0) -> 0.16313429 | R32: 22928.504 | S32: =N32-R32 -> 5025.02 | T32: =IFERROR(N32/R32-1,0) -> 0.2191604
F33: =SUM(F27:F32) -> 11678836 | G33: =SUM(G27:G32) -> 12358814 | H33: =F33-G33 -> -679977.89 | I33: =IFERROR(F33/G33-1,0) -> -0.05501967 | J33: =SUM(J27:J32) -> 15509709 | K33: =F33-J33 -> -3830872.8 | L33: =IFERROR(F33/J33-1,0) -> -0.24699836 | N33: =SUM(N27:N32) -> 312968.8 | O33: =SUM(O27:O32) -> 371786.05 | P33: =N33-O33 -> -58817.259 | Q33: =IFERROR(N33/O33-1,0) -> -0.1582019 | R33: =SUM(R27:R32) -> 417644.47 | S33: =N33-R33 -> -104675.67 | T33: =IFERROR(N33/R33-1,0) -> -0.25063344
F37: FEBRERO
C38: OCCIDENTE | F38: KILOS | J38: PESOS
A39: Vend | B39: Cte | C39: Nombre | D39: Código | E39: Descripcion | F39: Pres | G39: 2020 | H39: DIF | I39: % | J39: Pres | K39: 2020 | L39: DIF | M39: %
A40: 1 | B40: 327 | C40: EMPACADORAS UNIDAS DE LA PIEDAD SA DE CV | D40: PRO5500 | E40: APROPORK BOL 25 Kg | F40: 288.75 | G40: 40 | H40: -248.75 | I40: -0.86147186 | J40: 37349.668 | K40: 4732.22 | L40: -32617.448 | M40: -0.87329954
A41: 1 | B41: 481 | C41: GRUPO BRAVO NUÑO S.C. DE R.L. DE C.V. | D41: PROAPR | E41: APRORED BOLSA 1KG | F41: 84 | G41: 0 | H41: -84 | I41: -1 | J41: 21388.5 | K41: 0 | L41: -21388.5 | M41: -1
A42: 1 | B42: 313 | C42: CARNES FINAS DE LA SIERRA SA DE CV | D42: PROAPR | E42: APRORED BOLSA 1KG | F42: 42 | G42: 0 | H42: -42 | I42: -1 | J42: 12276.999 | K42: 0 | L42: -12276.999 | M42: -1
A43: 1 | B43: 485 | C43: PRODUCTOS EL GRAN CHAPARRAL SA DE CV | D43: PROAPR | E43: APRORED BOLSA 1KG | F43: 42 | G43: 0 | H43: -42 | I43: -1 | J43: 12276.999 | K43: 0 | L43: -12276.999 | M43: -1
A44: 1 | B44: 657 | C44: HECTOR ALONSO ZARATE QUIROZ | D44: PROAPR | E44: APRORED BOLSA 1KG | F44: 31.5 | G44: 0 | H44: -31.5 | I44: -1 | J44: 9207.7493 | K44: 0 | L44: -9207.7493 | M44: -1
A45: 1 | B45: 038 | C45: EMPACADORA BONNACARNE SA DE CV | D45: PROAPR | E45: APRORED BOLSA 1KG | F45: 21 | G45: 0 | H45: -21 | I45: -1 | J45: 6288.219 | K45: 0 | L45: -6288.219 | M45: -1
A46: 1 | B46: 009 | C46: EMPACADORA EL CENTENARIO, SA DE CV | D46: PROAPR | E46: APRORED BOLSA 1KG | F46: 10.5 | G46: 0 | H46: -10.5 | I46: -1 | J46: 3069.2497 | K46: 0 | L46: -3069.2497 | M46: -1
A47: 1 | B47: 476 | C47: OMEX ALIMENTARIA SA DE CV | D47: PROAPR | E47: APRORED BOLSA 1KG | F47: 5.25 | G47: 2 | H47: -3.25 | I47: -0.61904762 | J47: 1572.0548 | K47: 549.18 | L47: -1022.8747 | M47: -0.65066102
A48: 1 | B48: 038 | C48: EMPACADORA BONNACARNE SA DE CV | D48: PROAPR10 | E48: COM0213 APRORED BOLSA 10KG | F48: 0 | G48: 2.15 | H48: 2.15 | I48: 0 | J48: 0 | K48: 604.37 | L48: 604.37 | M48: 0
A49: 1 | B49: 476 | C49: OMEX ALIMENTARIA SA DE CV | D49: PROAPR10 | E49: COM0213 APRORED BOLSA 10KG | F49: 0 | G49: 10 | H49: 10 | I49: 0 | J49: 0 | K49: 2740.93 | L49: 2740.93 | M49: 0
...

Sheet MARZO
C1: CALCULO DE BONOS MARZO
C3: REGION OCCIDENTE
C5: KILOS | E5: Variacion | G5: PESOS | I5: Variacion
B6: MES | C6: Presupuesto | D6: Real | E6: KG | F6: % | G6: Presupuesto | H6: Real | I6: $ | J6: %
B7: MARZO | C7: ='ESSENTIA MAR'!O30 -> 145029.94 | D7: ='ESSENTIA MAR'!N30 -> 197180.65 | E7: =D7-C7 -> 52150.708 | F7: =D7/C7-1 -> 0.3595858 | G7: ='ESSENTIA MAR'!G30 -> 4337268.9 | H7: ='ESSENTIA MAR'!F30 -> 5866628.9 | I7: =H7-G7 -> 1529360 | J7: =H7/G7-1 -> 0.35260898
B9: COMPOSICION BONO | G9: ALCANCE DE OBJETIVOS
B10: Bono | C10: Concepto | D10: % Bono | E10: Monto | G10: Concepto | H10: Presupuesto | I10: Real | J10: % Cobertura | K10: Bono | M10: Objetivo Minimo
B11: 12000 | C11: Cumplimiento Presupuesto | D11: 0.7 | E11: =B11*D11 -> 8400 | G11: Cumplimiento Presupuesto | H11: =G7 -> 4337268.9 | I11: =H7 -> 5866628.9 | J11: =IFERROR(I11/H11,0) -> 1.352609 | K11: =IF(J11<M11,0,J11*$E11) -> 11361.915 | M11: 0.9
C12: Cierre de 3 pedidos 1000 Kgcon clientes actuales de FMC | D12: 0.12 | E12: =B11*D12 -> 1440 | G12: =C12 -> Cierre de 3 pedidos 1000 Kgcon clientes actuales de FMC | H12: 1 | J12: =I12/H12 -> 0 | K12: =IF(J12<M12,0,J12*$E12) -> 0 | M12: 0.8
C13: Contar con calendario de pruebas inicios de año 2020 | D13: 0.05 | E13: =B$11*D$13 -> 600 | G13: =C13 -> Contar con calendario de pruebas inicios de año 2020 | H13: 1 | J13: =I13/H13 -> 0 | K13: =IF(J13<M13,0,J13*$E13) -> 0 | M13: 1
C14: Presentar estrategica por region Occidente 2020 | D14: 0.05 | E14: =B$11*D$13 -> 600 | G14: =C14 -> Presentar estrategica por region Occidente 2020 | H14: 1 | J14: =I14/H14 -> 0 | K14: =IF(J14<M14,0,J14*$E14) -> 0 | M14: 0.75
C15: Presentar presupuesto lunes 6 de Diciembre | D15: 0.08 | E15: =B11*D15 -> 960 | G15: =C15 -> Presentar presupuesto lunes 6 de Diciembre | H15: 1 | J15: =I15/H15 -> 0 | K15: =IF(J15<M15,0,J15*$E15) -> 0 | M15: 0.75
C16: Total | D16: =SUM(D11:D15) -> 1 | E16: =SUM(E11:E15) -> 12000 | J16: Total sin Presupuesto | K16: =SUM(K12:K15) -> 0
J18: TOTAL | K18: =+K16+K11 -> 11361.915
C24: REGION PACIFICO
C26: KILOS | E26: Variacion | G26: PESOS | I26: Variacion
B27: MES | C27: Presupuesto | D27: Real | E27: KG | F27: % | G27: Presupuesto | H27: Real | I27: $ | J27: %
B28: =$B$7 -> MARZO | C28: ='ESSENTIA MAR'!O31 -> 40269.12 | D28: ='ESSENTIA MAR'!N31 -> 28197.388 | E28: =D28-C28 -> -12071.732 | F28: =D28/C28-1 -> -0.2997764 | G28: ='ESSENTIA MAR'!G31 -> 2513753.7 | H28: ='ESSENTIA MAR'!F31 -> 2114853.9 | I28: =H28-G28 -> -398899.75 | J28: =H28/G28-1 -> -0.15868689
B30: COMPOSICION BONO
B31: Bono | C31: Concepto | D31: % Bono | E31: Monto | F31: Objetivo Minimo | G31: Concepto | H31: Presupuesto | I31: Real | J31: % Cobertura | K31: Bono | M31: Objetivo Minimo
B32: 1000 | C32: Cumplimiento Presupuesto | D32: =E32/$B$37 -> 0.15384615 | E32: 1000 | F32: 0.5 | G32: =C32 -> Cumplimiento Presupuesto | H32: =G28 -> 2513753.7 | I32: =H28 -> 2114853.9 | J32: =IFERROR(I32/H32,0) -> 0.84131311 | K32: =IF(J32<M32,0,J32*$E32) -> 841.31311 | M32: 0.5
B33: 1000 | C33: Pruebas atorizadas por realizar con cliente | D33: =E33/$B$37 -> 0.15384615 | E33: 1000 | F33: 1 | G33: =C33 -> Pruebas atorizadas por realizar con cliente | H33: 1 | J33: =IFERROR(I33/H33,0) -> 0 | K33: =IF(J33<M33,0,J33*$E33) -> 0 | M33: 1
B34: 1500 | C34: Armado e implementación estrategia Baja California | D34: =E34/$B$37 -> 0.23076923 | E34: 1500 | F34: 1 | G34: =C34 -> Armado e implementación estrategia Baja California | H34: 1 | J34: =IFERROR(I34/H34,0) -> 0 | K34: =IF(J34<M34,0,J34*$E34) -> 0 | M34: 1
B35: 1500 | C35: Presentar estrategica por región 2020 | D35: =E35/$B$37 -> 0.23076923 | E35: 1500 | F35: 0.75 | G35: =C35 -> Presentar estrategica por región 2020 | H35: 1 | J35: =IFERROR(I35/H35,0) -> 0 | K35: =IF(J35<M35,0,J35*$E35) -> 0 | M35: 0.75
B36: 1500 | C36: Presentar presupuesto lunes 6 de Diciembre | D36: =E36/$B$37 -> 0.23076923 | E36: 1500 | F36: 0.75 | G36: =C36 -> Presentar presupuesto lunes 6 de Diciembre | H36: 1 | J36: =IFERROR(I36/H36,0) -> 0 | K36: =IF(J36<M36,0,J36*$E36) -> 0 | M36: 0.75
B37: =SUM(B32:B36) -> 6500 | C37: Total | E37: =SUM(E31:E36) -> 6500 | J37: Total sin Presupuesto | K37: =SUM(K34:K34) -> 0
J39: TOTAL | K39: =+K37+K32 -> 841.31311
C43: REGION BAJIO
C45: KILOS | E45: Variacion | G45: PESOS | I45: Variacion
B46: MES | C46: Presupuesto | D46: Real | E46: KG | F46: % | G46: Presupuesto | H46: Real | I46: $ | J46: %
B47: =$B$7 -> MARZO | C47: ='ESSENTIA MAR'!O36 -> 25555.395 | D47: ='ESSENTIA MAR'!N36 -> 36261.15 | E47: =D47-C47 -> 10705.755 | F47: =D47/C47-1 -> 0.41892346 | G47: ='ESSENTIA MAR'!G36 -> 1472297 | H47: ='ESSENTIA MAR'!F36 -> 2063580.4 | I47: =H47-G47 -> 591283.4 | J47: =H47/G47-1 -> 0.40160607
B49: COMPOSICION BONO | G49: ALCANCE DE OBJETIVOS
B50: Bono | C50: Concepto | D50: % Bono | E50: Monto | G50: Concepto | H50: Presupuesto | I50: Real | J50: % Cobertura | K50: Bono
B51: 7000 | C51: Cumplimiento Presupuesto | D51: 0.5 | E51: =B51*D51 -> 3500 | G51: =C51 -> Cumplimiento Presupuesto | H51: =G47 -> 1472297 | I51: =H47 -> 2063580.4 | J51: =IFERROR(I51/H51,0) -> 1.4016061 | K51: =IF(J51<M52,0,J51*$E51) -> 4905.6212 | M51: Objetivo Minimo
C52: Aplicación de pruebas unidades de chorizo | D52: 0.2 | E52: =B51*D52 -> 1400 | G52: =C52 -> Aplicación de pruebas unidades de chorizo | H52: 1 | J52: =IFERROR(I52/H52,0) -> 0 | K52: =IF(J52<M53,0,J52*$E52) -> 0 | M52: 0.95
C53: Prospectación | D53: 0.2 | E53: =B51*D53 -> 1400 | G53: =C53 -> Prospectación | H53: 1 | J53: =IFERROR(I53/H53,0) -> 0 | K53: =IF(J53<M54,0,J53*$E53) -> 0 | M53: 0.75
C54: Cierre de venta con productos nuevos AGR | D54: 0.1 | E54: =+D54*B51 -> 700 | G54: =C54 -> Cierre de venta con productos nuevos AGR | H54: 1 | J54: =IFERROR(I54/H54,0) -> 0 | K54: =IF(J54<M55,0,J54*$E54) -> 0 | M54: 0.75
C55: Total | D55: =SUM(D51:D54) -> 1 | E55: =SUM(E51:E54) -> 7000 | J55: Total sin Presupuesto | K55: =SUM(K52:K54) -> 0 | M55: 0.75
J57: TOTAL | K57: =+K55+K51 -> 4905.6212
C61: ALTOS NORTE
...

Sheet ESSENTIA MAR
E3: PRESUPUESTO ORIGINAL | F3: Importes | N3: Kilogramos
D4: Clave | E4: Region | F4: 2020 | G4: Pres | H4: Dif | I4: % Inc | J4: 2019 | K4: Dif | L4: % Inc | N4: 2020 | O4: Pres | P4: Dif | Q4: % Inc | R4: 2019 | S4: Dif | T4: % Inc
D5: 1 | E5: Occidente | F5: 5866628.9 | G5: 4375397.8 | H5: 1491231 | I5: 0.34082182 | J5: 5842159.2 | K5: 24469.71 | L5: 0.0041884703 | N5: 197180.65 | O5: 145378.44 | P5: 51802.208 | Q5: 0.35632661 | R5: 173656.21 | S5: 23524.439 | T5: 0.13546558
D6: 2 | E6: Pacifico | F6: 2114853.9 | G6: 2519579.5 | H6: -404725.57 | I6: -0.16063219 | J6: 2674387.9 | K6: -559534.01 | L6: -0.20921947 | N6: 28197.388 | O6: 40319.12 | P6: -12121.732 | Q6: -0.30064476 | R6: 47224.03 | S6: -19026.642 | T6: -0.4029017
D7: 3 | E7: Coordinadora de Ventas | F7: 2003033 | G7: 1692873.7 | H7: 310159.27 | I7: 0.18321465 | J7: 1403179.9 | K7: 599853.09 | L7: 0.42749549 | N7: 80334.684 | O7: 62937.68 | P7: 17397.004 | Q7: 0.27641635 | R7: 36118.064 | S7: 44216.62 | T7: 1.2242245
D8: 4 | E8: Cuentas Clave | F8: 1402135.6 | G8: 2122986.7 | H8: -720851.19 | I8: -0.33954578 | J8: 1816329.8 | K8: -414194.21 | L8: -0.2280391 | N8: 53684.4 | O8: 103176.28 | P8: -49491.88 | Q8: -0.47968273 | R8: 79547.88 | S8: -25863.48 | T8: -0.32513098
D9: 5 | E9: Mexico | F9: 145340.3 | G9: 176526.42 | H9: -31186.12 | I9: -0.17666545 | J9: 191931.4 | K9: -46591.1 | L9: -0.24274871 | N9: 150 | O9: 200 | P9: -50 | Q9: -0.25 | R9: 230 | S9: -80 | T9: -0.34782609
D10: 6 | E10: Altos Norte | F10: 1301053.4 | G10: 1092915.9 | H10: 208137.54 | I10: 0.19044241 | J10: 1394843.9 | K10: -93790.47 | L10: -0.067240835 | N10: 22354.082 | O10: 26525.09 | P10: -4171.008 | Q10: -0.15724765 | R10: 25602.36 | S10: -3248.2779 | T10: -0.12687416
D11: 7 | E11: Bajio | F11: 2063580.4 | G11: 1498300 | H11: 565280.33 | I11: 0.37728113 | J11: 1359435.8 | K11: 704144.57 | L11: 0.51796824 | N11: 36261.15 | O11: 25644.645 | P11: 10616.505 | Q11: 0.41398524 | R11: 24423.472 | S11: 11837.678 | T11: 0.4846845
F12: =SUM(F5:F11) -> 14896625 | G12: =SUM(G5:G11) -> 13478580 | H12: =F12-G12 -> 1418045.3 | I12: =IFERROR(F12/G12-1,0) -> 0.10520732 | J12: =SUM(J5:J11) -> 14682268 | K12: =F12-J12 -> 214357.58 | L12: =IFERROR(F12/J12-1,0) -> 0.01459976 | N12: =SUM(N5:N11) -> 418162.36 | O12: =SUM(O5:O11) -> 404181.26 | P12: =N12-O12 -> 13981.097 | Q12: =IFERROR(N12/O12-1,0) -> 0.034591155 | R12: =SUM(R5:R11) -> 386802.02 | S12: =N12-R12 -> 31360.337 | T12: =IFERROR(N12/R12-1,0) -> 0.081075941
E15: PERDIDA VENTA ESSENTIA | F15: Importes | N15: Kilogramos
D16: Clave | E16: Region | F16: 2020 | G16: Pres | H16: Dif | I16: % Inc | J16: 2019 | K16: Dif | L16: % Inc | N16: 2020 | O16: Pres | P16: Dif | Q16: % Inc | R16: 2019 | S16: Dif | T16: % Inc
D17: 1 | E17: Occidente | G17: =SUM(L44:L55) -> -38128.941 | O17: =SUM(H44:H55) -> -348.5
D18: 2 | E18: Pacifico | G18: =SUM(L63:L65) -> -5825.8175 | O18: =SUM(H63:H65) -> -50
D19: 3 | E19: Coordinadora de Ventas | G19: =SUM(L73:L74) -> -11085.327 | O19: =SUM(H73:H74) -> -65
D20: 4 | E20: Cuentas Clave
D21: 5 | E21: Mexico
D22: 6 | E22: Altos Norte | G22: =SUM(L82:L88) -> -53557.191 | O22: =SUM(H82:H88) -> -243
D23: 7 | E23: Bajio | G23: =SUM(L96:L97) -> -26003.069 | O23: =SUM(H96:H97) -> -89.25
F24: =SUM(F17:F23) -> 0 | G24: =SUM(G17:G23) -> -134600.35 | H24: =F24-G24 -> 134600.35 | I24: =IFERROR(F24/G24-1,0) -> -1 | J24: =SUM(J17:J23) -> 0 | K24: =F24-J24 -> 0 | L24: =IFERROR(F24/J24-1,0) -> 0 | N24: =SUM(N17:N23) -> 0 | O24: =SUM(O17:O23) -> -795.75 | P24: =N24-O24 -> 795.75 | Q24: =IFERROR(N24/O24-1,0) -> -1 | R24: =SUM(R17:R23) -> 0 | S24: =N24-R24 -> 0 | T24: =IFERROR(N24/R24-1,0) -> 0
E28: PRESUPUESTO MODIFICADO | F28: Importes | N28: Kilogramos
D29: Clave | E29: Region | F29: 2020 | G29: Pres | H29: Dif | I29: % Inc | J29: 2019 | K29: Dif | L29: % Inc | N29: 2020 | O29: Pres | P29: Dif | Q29: % Inc | R29: 2019 | S29: Dif | T29: % Inc
D30: 1 | E30: Occidente | F30: =F5 -> 5866628.9 | G30: =G5+G17 -> 4337268.9 | H30: =F30-G30 -> 1529360 | I30: =IFERROR(F30/G30-1,0) -> 0.35260898 | J30: 5842159.2 | K30: =F30-J30 -> 24469.71 | L30: =IFERROR(F30/J30-1,0) -> 0.0041884703 | N30: =N5 -> 197180.65 | O30: =O5+O17 -> 145029.94 | P30: =N30-O30 -> 52150.708 | Q30: =IFERROR(N30/O30-1,0) -> 0.3595858 | R30: 173656.21 | S30: =N30-R30 -> 23524.439 | T30: =IFERROR(N30/R30-1,0) -> 0.13546558
D31: 2 | E31: Pacifico | F31: =F6 -> 2114853.9 | G31: =G6+G18 -> 2513753.7 | H31: =F31-G31 -> -398899.75 | I31: =IFERROR(F31/G31-1,0) -> -0.15868689 | J31: 2674387.9 | K31: =F31-J31 -> -559534.01 | L31: =IFERROR(F31/J31-1,0) -> -0.20921947 | N31: =N6 -> 28197.388 | O31: =O6+O18 -> 40269.12 | P31: =N31-O31 -> -12071.732 | Q31: =IFERROR(N31/O31-1,0) -> -0.2997764 | R31: 47224.03 | S31: =N31-R31 -> -19026.642 | T31: =IFERROR(N31/R31-1,0) -> -0.4029017
D32: 3 | E32: Coordinadora de Ventas | F32: =F7 -> 2003033 | G32: =G7+G19 -> 1681788.4 | H32: =F32-G32 -> 321244.6 | I32: =IFERROR(F32/G32-1,0) -> 0.19101368 | J32: 1403179.9 | K32: =F32-J32 -> 599853.09 | L32: =IFERROR(F32/J32-1,0) -> 0.42749549 | N32: =N7 -> 80334.684 | O32: =O7+O19 -> 62872.68 | P32: =N32-O32 -> 17462.004 | Q32: =IFERROR(N32/O32-1,0) -> 0.27773596 | R32: 36118.064 | S32: =N32-R32 -> 44216.62 | T32: =IFERROR(N32/R32-1,0) -> 1.2242245
F33: =F8 -> 1402135.6 | G33: =G8+G20 -> 2122986.7 | H33: =F33-G33 -> -720851.19 | I33: =IFERROR(F33/G33-1,0) -> -0.33954578 | J33: 1816329.8 | K33: =F33-J33 -> -414194.21 | L33: =IFERROR(F33/J33-1,0) -> -0.2280391 | N33: =N8 -> 53684.4 | O33: =O8+O20 -> 103176.28 | P33: =N33-O33 -> -49491.88 | Q33: =IFERROR(N33/O33-1,0) -> -0.47968273 | R33: 79547.88 | S33: =N33-R33 -> -25863.48 | T33: =IFERROR(N33/R33-1,0) -> -0.32513098
D34: 5 | E34: Mexico | F34: =F9 -> 145340.3 | G34: =G9+G21 -> 176526.42 | H34: =F34-G34 -> -31186.12 | I34: =IFERROR(F34/G34-1,0) -> -0.17666545 | J34: 191931.4 | K34: =F34-J34 -> -46591.1 | L34: =IFERROR(F34/J34-1,0) -> -0.24274871 | N34: =N9 -> 150 | O34: =O9+O21 -> 200 | P34: =N34-O34 -> -50 | Q34: =IFERROR(N34/O34-1,0) -> -0.25 | R34: 230 | S34: =N34-R34 -> -80 | T34: =IFERROR(N34/R34-1,0) -> -0.34782609
D35: 6 | E35: Altos Norte | F35: =F10+F8 -> 2703189 | G35: =+G8+G10+G22 -> 3162345.5 | H35: =F35-G35 -> -459156.46 | I35: =IFERROR(F35/G35-1,0) -> -0.14519491 | J35: =J10+J8 -> 3211173.7 | K35: =F35-J35 -> -507984.68 | L35: =IFERROR(F35/J35-1,0) -> -0.15819284 | N35: =N10+N8 -> 76038.482 | O35: =+O8+O10+O22 -> 129458.37 | P35: =N35-O35 -> -53419.888 | Q35: =IFERROR(N35/O35-1,0) -> -0.41264144 | R35: 25602.36 | S35: =N35-R35 -> 50436.122 | T35: =IFERROR(N35/R35-1,0) -> 1.9699794
D36: 7 | E36: Bajio | F36: =F11 -> 2063580.4 | G36: =G11+G23 -> 1472297 | H36: =F36-G36 -> 591283.4 | I36: =IFERROR(F36/G36-1,0) -> 0.40160607 | J36: 1359435.8 | K36: =F36-J36 -> 704144.57 | L36: =IFERROR(F36/J36-1,0) -> 0.51796824 | N36: =N11 -> 36261.15 | O36: =O11+O23 -> 25555.395 | P36: =N36-O36 -> 10705.755 | Q36: =IFERROR(N36/O36-1,0) -> 0.41892346 | R36: 24423.472 | S36: =N36-R36 -> 11837.678 | T36: =IFERROR(N36/R36-1,0) -> 0.4846845
F37: =SUM(F30:F36) -> 16298761 | G37: =SUM(G30:G36) -> 15466967 | H37: =F37-G37 -> 831794.46 | I37: =IFERROR(F37/G37-1,0) -> 0.053778772 | J37: =SUM(J30:J36) -> 16498598 | K37: =F37-J37 -> -199836.63 | L37: =IFERROR(F37/J37-1,0) -> -0.01211234 | N37: =SUM(N30:N36) -> 471846.76 | O37: =SUM(O30:O36) -> 506561.79 | P37: =N37-O37 -> -34715.033 | Q37: =IFERROR(N37/O37-1,0) -> -0.068530699 | R37: =SUM(R30:R36) -> 386802.02 | S37: =N37-R37 -> 85044.737 | T37: =IFERROR(N37/R37-1,0) -> 0.21986632
F41: MARZO
C42: OCCIDENTE | F42: KILOS | J42: PESOS
A43: Vend | B43: Cte | C43: Nombre | D43: Código | E43: Descripcion | F43: Pres | G43: 2020 | H43: DIF | I43: % | J43: Pres | K43: 2020 | L43: DIF | M43: %
A44: 1 | B44: 009 | C44: EMPACADORA EL CENTENARIO, SA DE CV | D44: PRO5500 | E44: APROPORK BOL 25 Kg | F44: 787.5 | G44: 720 | H44: -67.5 | I44: -0.085714286 | J44: 104268.94 | K44: 99594 | L44: -4674.9375 | M44: -0.044835381
A45: 1 | B45: 009 | C45: EMPACADORA EL CENTENARIO, SA DE CV | D45: PROAPR | E45: APRORED BOLSA 1KG | F45: 12.6 | G45: 0 | H45: -12.6 | I45: -1 | J45: 3683.0997 | K45: 0 | L45: -3683.0997 | M45: -1
A46: 1 | B46: 038 | C46: EMPACADORA BONNACARNE SA DE CV | D46: PROAPR | E46: APRORED BOLSA 1KG | F46: 15.75 | G46: 10 | H46: -5.75 | I46: -0.36507937 | J46: 4716.1642 | K46: 3118.31 | L46: -1597.8543 | M46: -0.33880377
A47: 1 | B47: 099 | C47: COMERCIALIZADORA DE EMBUTIDOS ICO SA DE CV | D47: PROAPR | E47: APRORED BOLSA 1KG | F47: 3.15 | G47: 0 | H47: -3.15 | I47: -1 | J47: 891.90045 | K47: 0 | L47: -891.90045 | M47: -1
A48: 1 | B48: 476 | C48: OMEX ALIMENTARIA SA DE CV | D48: PROAPR | E48: APRORED BOLSA 1KG | F48: 10.5 | G48: 7 | H48: -3.5 | I48: -0.33333333 | J48: 3144.1095 | K48: 2095.24 | L48: -1048.8695 | M48: -0.33359827
A49: 1 | B49: 481 | C49: GRUPO BRAVO NUÑO S.C. DE R.L. DE C.V. | D49: PROAPR | E49: APRORED BOLSA 1KG | F49: 126 | G49: 250 | H49: 124 | I49: 0.98412698 | J49: 32082.75 | K49: 60261.56 | L49: 28178.81 | M49: 0.87831654
A50: 1 | B50: 485 | C50: PRODUCTOS EL GRAN CHAPARRAL SA DE CV | D50: PROAPR | E50: APRORED BOLSA 1KG | F50: 42 | G50: 30 | H50: -12 | I50: -0.28571429 | J50: 12276.999 | K50: 9200.23 | L50: -3076.769 | M50: -0.25061247
...

Sheet ABRIL
C1: CALCULO DE BONOS ABRIL
C3: REGION OCCIDENTE
C5: KILOS | E5: Variacion | G5: PESOS | I5: Variacion
B6: MES | C6: Presupuesto | D6: Real | E6: KG | F6: % | G6: Presupuesto | H6: Real | I6: $ | J6: %
B7: ABRIL | C7: ='ESSENTIA ABR'!O30 -> 158697.14 | D7: ='ESSENTIA ABR'!N30 -> 132874.53 | E7: =D7-C7 -> -25822.611 | F7: =D7/C7-1 -> -0.1627163 | G7: ='ESSENTIA ABR'!G30 -> 4780259.9 | H7: ='ESSENTIA ABR'!F30 -> 5313807.2 | I7: =H7-G7 -> 533547.23 | J7: =H7/G7-1 -> 0.11161469
B9: COMPOSICION BONO | G9: ALCANCE DE OBJETIVOS
B10: Bono | C10: Concepto | D10: % Bono | E10: Monto | G10: Concepto | H10: Presupuesto | I10: Real | J10: % Cobertura | K10: Bono | M10: Objetivo Minimo
B11: 12000 | C11: Cumplimiento Presupuesto | D11: 0.7 | E11: =B11*D11 -> 8400 | G11: Cumplimiento Presupuesto | H11: =G7 -> 4780259.9 | I11: =H7 -> 5313807.2 | J11: =IFERROR(I11/H11,0) -> 1.1116147 | K11: =IF(J11<M11,0,J11*$E11) -> 9337.5634 | M11: 0.9
C12: Cierre de 3 pedidos 1000 Kgcon clientes actuales de FMC | D12: 0.12 | E12: =B11*D12 -> 1440 | G12: =C12 -> Cierre de 3 pedidos 1000 Kgcon clientes actuales de FMC | H12: 1 | J12: =I12/H12 -> 0 | K12: =IF(J12<M12,0,J12*$E12) -> 0 | M12: 0.8
C13: Contar con calendario de pruebas inicios de año 2020 | D13: 0.05 | E13: =B$11*D$13 -> 600 | G13: =C13 -> Contar con calendario de pruebas inicios de año 2020 | H13: 1 | J13: =I13/H13 -> 0 | K13: =IF(J13<M13,0,J13*$E13) -> 0 | M13: 1
C14: Presentar estrategica por region Occidente 2020 | D14: 0.05 | E14: =B$11*D$13 -> 600 | G14: =C14 -> Presentar estrategica por region Occidente 2020 | H14: 1 | J14: =I14/H14 -> 0 | K14: =IF(J14<M14,0,J14*$E14) -> 0 | M14: 0.75
C15: Presentar presupuesto lunes 6 de Diciembre | D15: 0.08 | E15: =B11*D15 -> 960 | G15: =C15 -> Presentar presupuesto lunes 6 de Diciembre | H15: 1 | J15: =I15/H15 -> 0 | K15: =IF(J15<M15,0,J15*$E15) -> 0 | M15: 0.75
C16: Total | D16: =SUM(D11:D15) -> 1 | E16: =SUM(E11:E15) -> 12000 | J16: Total sin Presupuesto | K16: =SUM(K12:K15) -> 0
J18: TOTAL | K18: =+K16+K11 -> 9337.5634
C24: REGION PACIFICO
C26: KILOS | E26: Variacion | G26: PESOS | I26: Variacion
B27: MES | C27: Presupuesto | D27: Real | E27: KG | F27: % | G27: Presupuesto | H27: Real | I27: $ | J27: %
B28: =$B$7 -> ABRIL | C28: ='ESSENTIA ABR'!O31 -> 31844 | D28: ='ESSENTIA ABR'!N31 -> 16035.98 | E28: =D28-C28 -> -15808.02 | F28: =D28/C28-1 -> -0.49642068 | G28: ='ESSENTIA ABR'!G31 -> 2220021.1 | H28: ='ESSENTIA ABR'!F31 -> 1066299.4 | I28: =H28-G28 -> -1153721.8 | J28: =H28/G28-1 -> -0.51968955
B30: COMPOSICION BONO
B31: Bono | C31: Concepto | D31: % Bono | E31: Monto | F31: Objetivo Minimo | G31: Concepto | H31: Presupuesto | I31: Real | J31: % Cobertura | K31: Bono | M31: Objetivo Minimo
B32: 1000 | C32: Cumplimiento Presupuesto | D32: =E32/$B$37 -> 0.15384615 | E32: 1000 | F32: 0.5 | G32: =C32 -> Cumplimiento Presupuesto | H32: =G28 -> 2220021.1 | I32: =H28 -> 1066299.4 | J32: =IFERROR(I32/H32,0) -> 0.48031045 | K32: =IF(J32<M32,0,J32*$E32) -> 0 | M32: 0.5
B33: 1000 | C33: Pruebas atorizadas por realizar con cliente | D33: =E33/$B$37 -> 0.15384615 | E33: 1000 | F33: 1 | G33: =C33 -> Pruebas atorizadas por realizar con cliente | H33: 1 | J33: =IFERROR(I33/H33,0) -> 0 | K33: =IF(J33<M33,0,J33*$E33) -> 0 | M33: 1
B34: 1500 | C34: Armado e implementación estrategia Baja California | D34: =E34/$B$37 -> 0.23076923 | E34: 1500 | F34: 1 | G34: =C34 -> Armado e implementación estrategia Baja California | H34: 1 | J34: =IFERROR(I34/H34,0) -> 0 | K34: =IF(J34<M34,0,J34*$E34) -> 0 | M34: 1
B35: 1500 | C35: Presentar estrategica por región 2020 | D35: =E35/$B$37 -> 0.23076923 | E35: 1500 | F35: 0.75 | G35: =C35 -> Presentar estrategica por región 2020 | H35: 1 | J35: =IFERROR(I35/H35,0) -> 0 | K35: =IF(J35<M35,0,J35*$E35) -> 0 | M35: 0.75
B36: 1500 | C36: Presentar presupuesto lunes 6 de Diciembre | D36: =E36/$B$37 -> 0.23076923 | E36: 1500 | F36: 0.75 | G36: =C36 -> Presentar presupuesto lunes 6 de Diciembre | H36: 1 | J36: =IFERROR(I36/H36,0) -> 0 | K36: =IF(J36<M36,0,J36*$E36) -> 0 | M36: 0.75
B37: =SUM(B32:B36) -> 6500 | C37: Total | E37: =SUM(E31:E36) -> 6500 | J37: Total sin Presupuesto | K37: =SUM(K34:K34) -> 0
J39: TOTAL | K39: =+K37+K32 -> 0
C43: REGION BAJIO
C45: KILOS | E45: Variacion | G45: PESOS | I45: Variacion
B46: MES | C46: Presupuesto | D46: Real | E46: KG | F46: % | G46: Presupuesto | H46: Real | I46: $ | J46: %
B47: =$B$7 -> ABRIL | C47: ='ESSENTIA ABR'!O36 -> 28358.021 | D47: ='ESSENTIA ABR'!N36 -> 17999.54 | E47: =D47-C47 -> -10358.481 | F47: =D47/C47-1 -> -0.36527518 | G47: ='ESSENTIA ABR'!G36 -> 1902243 | H47: ='ESSENTIA ABR'!F36 -> 1128176.3 | I47: =H47-G47 -> -774066.69 | J47: =H47/G47-1 -> -0.40692313
B49: COMPOSICION BONO | G49: ALCANCE DE OBJETIVOS
B50: Bono | C50: Concepto | D50: % Bono | E50: Monto | G50: Concepto | H50: Presupuesto | I50: Real | J50: % Cobertura | K50: Bono
B51: 7000 | C51: Cumplimiento Presupuesto | D51: 0.5 | E51: =B51*D51 -> 3500 | G51: =C51 -> Cumplimiento Presupuesto | H51: =G47 -> 1902243 | I51: =H47 -> 1128176.3 | J51: =IFERROR(I51/H51,0) -> 0.59307687 | K51: =IF(J51<M52,0,J51*$E51) -> 0 | M51: Objetivo Minimo
C52: Aplicación de pruebas unidades de chorizo | D52: 0.2 | E52: =B51*D52 -> 1400 | G52: =C52 -> Aplicación de pruebas unidades de chorizo | H52: 1 | J52: =IFERROR(I52/H52,0) -> 0 | K52: =IF(J52<M53,0,J52*$E52) -> 0 | M52: 0.95
C53: Prospectación | D53: 0.2 | E53: =B51*D53 -> 1400 | G53: =C53 -> Prospectación | H53: 1 | J53: =IFERROR(I53/H53,0) -> 0 | K53: =IF(J53<M54,0,J53*$E53) -> 0 | M53: 0.75
C54: Cierre de venta con productos nuevos AGR | D54: 0.1 | E54: =+D54*B51 -> 700 | G54: =C54 -> Cierre de venta con productos nuevos AGR | H54: 1 | J54: =IFERROR(I54/H54,0) -> 0 | K54: =IF(J54<M55,0,J54*$E54) -> 0 | M54: 0.75
C55: Total | D55: =SUM(D51:D54) -> 1 | E55: =SUM(E51:E54) -> 7000 | J55: Total sin Presupuesto | K55: =SUM(K52:K54) -> 0 | M55: 0.75
J57: TOTAL | K57: =+K55+K51 -> 0
C61: ALTOS NORTE
...

Sheet ESSENTIA ABR
E3: PRESUPUESTO ORIGINAL | F3: Importes | N3: Kilogramos
D4: Clave | E4: Region | F4: 2020 | G4: Pres | H4: Dif | I4: % Inc | J4: 2019 | K4: Dif | L4: % Inc | N4: 2020 | O4: Pres | P4: Dif | Q4: % Inc | R4: 2019 | S4: Dif | T4: % Inc
D5: 1 | E5: Occidente | F5: 5313807.2 | G5: 4793765.6 | H5: =F5-G5 -> 520041.55 | I5: =IFERROR(F5/G5-1,0) -> 0.10848289 | J5: 5883519.2 | K5: =F5-J5 -> -569711.98 | L5: =IFERROR(F5/J5-1,0) -> -0.096831839 | N5: 132874.53 | O5: 158923.64 | P5: =N5-O5 -> -26049.111 | Q5: =IFERROR(N5/O5-1,0) -> -0.16390961 | R5: 179310.23 | S5: =N5-R5 -> -46435.698 | T5: =IFERROR(N5/R5-1,0) -> -0.25896848
D6: 2 | E6: Pacifico | F6: 1066299.4 | G6: 2222720.1 | H6: =F6-G6 -> -1156420.7 | I6: =IFERROR(F6/G6-1,0) -> -0.52027276 | J6: 2460058.2 | K6: =F6-J6 -> -1393758.8 | L6: =IFERROR(F6/J6-1,0) -> -0.56655522 | N6: 16035.98 | O6: 31844 | P6: =N6-O6 -> -15808.02 | Q6: =IFERROR(N6/O6-1,0) -> -0.49642068 | R6: 52118.003 | S6: =N6-R6 -> -36082.023 | T6: =IFERROR(N6/R6-1,0) -> -0.692314
D7: 3 | E7: Servicio al cliente | F7: 1569643 | G7: 1506074.1 | H7: =F7-G7 -> 63568.833 | I7: =IFERROR(F7/G7-1,0) -> 0.042208303 | J7: 1143991.1 | K7: =F7-J7 -> 425651.9 | L7: =IFERROR(F7/J7-1,0) -> 0.37207625 | N7: 38260.164 | O7: 47169 | P7: =N7-O7 -> -8908.836 | Q7: =IFERROR(N7/O7-1,0) -> -0.18887057 | R7: 37083.39 | S7: =N7-R7 -> 1176.7741 | T7: =IFERROR(N7/R7-1,0) -> 0.031733186
D8: 4 | E8: Cuentas Clave | F8: 2064306.8 | G8: 2252396 | H8: =F8-G8 -> -188089.15 | I8: =IFERROR(F8/G8-1,0) -> -0.083506254 | J8: 2279686.2 | K8: =F8-J8 -> -215379.4 | L8: =IFERROR(F8/J8-1,0) -> -0.094477651 | N8: 76524.32 | O8: 111960 | P8: =N8-O8 -> -35435.68 | Q8: =IFERROR(N8/O8-1,0) -> -0.31650304 | R8: 102460 | S8: =N8-R8 -> -25935.68 | T8: =IFERROR(N8/R8-1,0) -> -0.25312981
D9: 5 | E9: Mexico | F9: 203864.18 | G9: 150047.46 | H9: =F9-G9 -> 53816.723 | I9: =IFERROR(F9/G9-1,0) -> 0.35866468 | J9: 83401.35 | K9: =F9-J9 -> 120462.83 | L9: =IFERROR(F9/J9-1,0) -> 1.4443751 | N9: 200 | O9: 170 | P9: =N9-O9 -> 30 | Q9: =IFERROR(N9/O9-1,0) -> 0.17647059 | R9: 90.84 | S9: =N9-R9 -> 109.16 | T9: =IFERROR(N9/R9-1,0) -> 1.2016733
D10: 6 | E10: Altos Norte | F10: 1203406.2 | G10: 1134739.1 | H10: =F10-G10 -> 68667.126 | I10: =IFERROR(F10/G10-1,0) -> 0.060513583 | J10: 1435051.2 | K10: =F10-J10 -> -231645.05 | L10: =IFERROR(F10/J10-1,0) -> -0.16141936 | N10: 18591.502 | O10: 20501.24 | P10: =N10-O10 -> -1909.7381 | Q10: =IFERROR(N10/O10-1,0) -> -0.093152322 | R10: 24134.32 | S10: =N10-R10 -> -5542.8181 | T10: =IFERROR(N10/R10-1,0) -> -0.22966539
D11: 7 | E11: Bajio | F11: 1128176.3 | G11: 1900550 | H11: =F11-G11 -> -772373.64 | I11: =IFERROR(F11/G11-1,0) -> -0.40639481 | J11: 1674568 | K11: =F11-J11 -> -546391.7 | L11: =IFERROR(F11/J11-1,0) -> -0.32628815 | N11: 17999.54 | O11: 28360.021 | P11: =N11-O11 -> -10360.481 | Q11: =IFERROR(N11/O11-1,0) -> -0.36531994 | R11: 27009.544 | S11: =N11-R11 -> -9010.004 | T11: =IFERROR(N11/R11-1,0) -> -0.33358594
F12: =SUM(F5:F11) -> 12549503 | G12: =SUM(G5:G11) -> 13960292 | H12: =F12-G12 -> -1410789.3 | I12: =IFERROR(F12/G12-1,0) -> -0.10105729 | J12: =SUM(J5:J11) -> 14960275 | K12: =F12-J12 -> -2410772.2 | L12: =IFERROR(F12/J12-1,0) -> -0.16114491 | N12: =SUM(N5:N11) -> 300486.04 | O12: =SUM(O5:O11) -> 398927.9 | P12: =N12-O12 -> -98441.867 | Q12: =IFERROR(N12/O12-1,0) -> -0.24676606 | R12: =SUM(R5:R11) -> 422206.32 | S12: =N12-R12 -> -121720.29 | T12: =IFERROR(N12/R12-1,0) -> -0.28829575
E15: PERDIDA VENTA ESSENTIA | F15: Importes | N15: Kilogramos
D16: Clave | E16: Region | F16: 2020 | G16: Pres | H16: Dif | I16: % Inc | J16: 2019 | K16: Dif | L16: % Inc | N16: 2020 | O16: Pres | P16: Dif | Q16: % Inc | R16: 2019 | S16: Dif | T16: % Inc
D17: 1 | E17: Occidente | G17: =SUM(L44:L55) -> -13505.686 | O17: =SUM(H44:H55) -> -226.5
D18: 2 | E18: Pacifico | G18: =SUM(L63:L65) -> -2698.92 | O18: =SUM(H63:H65) -> 0
D19: 3 | E19: Coordinadora de Ventas | G19: =SUM(L73:L75) -> -5879.5225 | O19: =SUM(H73:H75) -> -35
D20: 4 | E20: Cuentas Clave
D21: 5 | E21: Mexico
D22: 6 | E22: Altos Norte | G22: =SUM(L83:L89) -> -47071.41 | O22: =SUM(H83:H89) -> -332
D23: 7 | E23: Bajio | G23: =SUM(L97:L98) -> 1693.049 | O23: =SUM(H97:H98) -> -2
F24: =SUM(F17:F23) -> 0 | G24: =SUM(G17:G23) -> -67462.489 | H24: =F24-G24 -> 67462.489 | I24: =IFERROR(F24/G24-1,0) -> -1 | J24: =SUM(J17:J23) -> 0 | K24: =F24-J24 -> 0 | L24: =IFERROR(F24/J24-1,0) -> 0 | N24: =SUM(N17:N23) -> 0 | O24: =SUM(O17:O23) -> -595.5 | P24: =N24-O24 -> 595.5 | Q24: =IFERROR(N24/O24-1,0) -> -1 | R24: =SUM(R17:R23) -> 0 | S24: =N24-R24 -> 0 | T24: =IFERROR(N24/R24-1,0) -> 0
E28: PRESUPUESTO MODIFICADO | F28: Importes | N28: Kilogramos
D29: Clave | E29: Region | F29: 2020 | G29: Pres | H29: Dif | I29: % Inc | J29: 2019 | K29: Dif | L29: % Inc | N29: 2020 | O29: Pres | P29: Dif | Q29: % Inc | R29: 2019 | S29: Dif | T29: % Inc
D30: 1 | E30: Occidente | F30: =F5 -> 5313807.2 | G30: =G5+G17 -> 4780259.9 | H30: =F30-G30 -> 533547.23 | I30: =IFERROR(F30/G30-1,0) -> 0.11161469 | J30: 5842159.2 | K30: =F30-J30 -> -528351.99 | L30: =IFERROR(F30/J30-1,0) -> -0.090437794 | N30: =N5 -> 132874.53 | O30: =O5+O17 -> 158697.14 | P30: =N30-O30 -> -25822.611 | Q30: =IFERROR(N30/O30-1,0) -> -0.1627163 | R30: 173656.21 | S30: =N30-R30 -> -40781.682 | T30: =IFERROR(N30/R30-1,0) -> -0.23484148
D31: 2 | E31: Pacifico | F31: =F6 -> 1066299.4 | G31: =G6+G18 -> 2220021.1 | H31: =F31-G31 -> -1153721.8 | I31: =IFERROR(F31/G31-1,0) -> -0.51968955 | J31: 2674387.9 | K31: =F31-J31 -> -1608088.6 | L31: =IFERROR(F31/J31-1,0) -> -0.60129219 | N31: =N6 -> 16035.98 | O31: =O6+O18 -> 31844 | P31: =N31-O31 -> -15808.02 | Q31: =IFERROR(N31/O31-1,0) -> -0.49642068 | R31: 47224.03 | S31: =N31-R31 -> -31188.05 | T31: =IFERROR(N31/R31-1,0) -> -0.66042754
D32: 3 | E32: Coordinadora de Ventas | F32: =F7 -> 1569643 | G32: =G7+G19 -> 1500194.6 | H32: =F32-G32 -> 69448.355 | I32: =IFERROR(F32/G32-1,0) -> 0.046292898 | J32: 1403179.9 | K32: =F32-J32 -> 166463.05 | L32: =IFERROR(F32/J32-1,0) -> 0.11863272 | N32: =N7 -> 38260.164 | O32: =O7+O19 -> 47134 | P32: =N32-O32 -> -8873.836 | Q32: =IFERROR(N32/O32-1,0) -> -0.18826826 | R32: 36118.064 | S32: =N32-R32 -> 2142.1001 | T32: =IFERROR(N32/R32-1,0) -> 0.059308276
D33: 4 | E33: Cuentas Clave | F33: =F8 -> 2064306.8 | G33: =G8+G20 -> 2252396 | H33: =F33-G33 -> -188089.15 | I33: =IFERROR(F33/G33-1,0) -> -0.083506254 | J33: 1816329.8 | K33: =F33-J33 -> 247977.06 | L33: =IFERROR(F33/J33-1,0) -> 0.13652645 | N33: =N8 -> 76524.32 | O33: =O8+O20 -> 111960 | P33: =N33-O33 -> -35435.68 | Q33: =IFERROR(N33/O33-1,0) -> -0.31650304 | R33: 79547.88 | S33: =N33-R33 -> -3023.56 | T33: =IFERROR(N33/R33-1,0) -> -0.03800931
D34: 5 | E34: Mexico | F34: =F9 -> 203864.18 | G34: =G9+G21 -> 150047.46 | H34: =F34-G34 -> 53816.723 | I34: =IFERROR(F34/G34-1,0) -> 0.35866468 | J34: 191931.4 | K34: =F34-J34 -> 11932.78 | L34: =IFERROR(F34/J34-1,0) -> 0.062172109 | N34: =N9 -> 200 | O34: =O9+O21 -> 170 | P34: =N34-O34 -> 30 | Q34: =IFERROR(N34/O34-1,0) -> 0.17647059 | R34: 230 | S34: =N34-R34 -> -30 | T34: =IFERROR(N34/R34-1,0) -> -0.13043478
D35: 6 | E35: Altos Norte | F35: =F10+F8 -> 3267713 | G35: =+G8+G10+G22 -> 3340063.6 | H35: =F35-G35 -> -72350.613 | I35: =IFERROR(F35/G35-1,0) -> -0.021661448 | J35: =J10+J8 -> 3714737.5 | K35: =F35-J35 -> -447024.45 | L35: =IFERROR(F35/J35-1,0) -> -0.1203381 | N35: =N10+N8 -> 95115.822 | O35: =+O8+O10+O22 -> 132129.24 | P35: =N35-O35 -> -37013.418 | Q35: =IFERROR(N35/O35-1,0) -> -0.28013041 | R35: 25602.36 | S35: =N35-R35 -> 69513.462 | T35: =IFERROR(N35/R35-1,0) -> 2.7151193
D36: 7 | E36: Bajio | F36: =F11 -> 1128176.3 | G36: =G11+G23 -> 1902243 | H36: =F36-G36 -> -774066.69 | I36: =IFERROR(F36/G36-1,0) -> -0.40692313 | J36: 1359435.8 | K36: =F36-J36 -> -231259.49 | L36: =IFERROR(F36/J36-1,0) -> -0.17011431 | N36: =N11 -> 17999.54 | O36: =O11+O23 -> 28358.021 | P36: =N36-O36 -> -10358.481 | Q36: =IFERROR(N36/O36-1,0) -> -0.36527518 | R36: 24423.472 | S36: =N36-R36 -> -6423.9318 | T36: =IFERROR(N36/R36-1,0) -> -0.26302288
F37: =SUM(F30:F36) -> 14613810 | G37: =SUM(G30:G36) -> 16145226 | H37: =F37-G37 -> -1531415.9 | I37: =IFERROR(F37/G37-1,0) -> -0.094852556 | J37: =SUM(J30:J36) -> 17002161 | K37: =F37-J37 -> -2388351.6 | L37: =IFERROR(F37/J37-1,0) -> -0.14047341 | N37: =SUM(N30:N36) -> 377010.36 | O37: =SUM(O30:O36) -> 510292.4 | P37: =N37-O37 -> -133282.05 | Q37: =IFERROR(N37/O37-1,0) -> -0.2611876 | R37: =SUM(R30:R36) -> 386802.02 | S37: =N37-R37 -> -9791.6617 | T37: =IFERROR(N37/R37-1,0) -> -0.025314402
F41: ABRIL
C42: OCCIDENTE | F42: KILOS | J42: PESOS
A43: Vend | B43: Cte | C43: Nombre | D43: Código | E43: Descripcion | F43: Pres | G43: 2020 | H43: DIF | I43: % | J43: Pres | K43: 2020 | L43: DIF | M43: %
A44: 1 | B44: 009 | C44: EMPACADORA EL CENTENARIO, SA DE CV | D44: PRO5500 | E44: APROPORK BOL 25 Kg | F44: 787.5 | G44: 740 | H44: =G44-F44 -> -47.5 | I44: =IFERROR(G44/F44-1,0) -> -0.06031746 | J44: 104268.94 | K44: 116257.62 | L44: =K44-J44 -> 11988.682 | M44: =IFERROR(K44/J44-1,0) -> 0.11497847
A45: 1 | B45: 009 | C45: EMPACADORA EL CENTENARIO, SA DE CV | D45: PROAPR | E45: APRORED BOLSA 1KG | F45: 11.55 | G45: 0 | H45: =G45-F45 -> -11.55 | I45: =IFERROR(G45/F45-1,0) -> -1 | J45: 3376.1747 | K45: 0 | L45: =K45-J45 -> -3376.1747 | M45: =IFERROR(K45/J45-1,0) -> -1
A46: 1 | B46: 038 | C46: EMPACADORA BONNACARNE SA DE CV | D46: PROAPR | E46: APRORED BOLSA 1KG | F46: 21 | G46: 0 | H46: =G46-F46 -> -21 | I46: =IFERROR(G46/F46-1,0) -> -1 | J46: 6288.219 | K46: 0 | L46: =K46-J46 -> -6288.219 | M46: =IFERROR(K46/J46-1,0) -> -1
A47: 1 | B47: 099 | C47: COMERCIALIZADORA DE EMBUTIDOS ICO SA DE CV | D47: PROAPR | E47: APRORED BOLSA 1KG | F47: 14.7 | G47: 0 | H47: =G47-F47 -> -14.7 | I47: =IFERROR(G47/F47-1,0) -> -1 | J47: 4162.2021 | K47: 0 | L47: =K47-J47 -> -4162.2021 | M47: =IFERROR(K47/J47-1,0) -> -1
A48: 1 | B48: 313 | C48: CARNES FINAS DE LA SIERRA SA DE CV | D48: PROAPR | E48: APRORED BOLSA 1KG | F48: 105 | G48: 0 | H48: =G48-F48 -> -105 | I48: =IFERROR(G48/F48-1,0) -> -1 | J48: 30692.498 | K48: 0 | L48: =K48-J48 -> -30692.498 | M48: =IFERROR(K48/J48-1,0) -> -1
A49: 1 | B49: 476 | C49: OMEX ALIMENTARIA SA DE CV | D49: PROAPR | E49: APRORED BOLSA 1KG | F49: 0 | G49: 5 | H49: =G49-F49 -> 5 | I49: =IFERROR(G49/F49-1,0) -> 0 | J49: 0 | K49: 1795.22 | L49: =K49-J49 -> 1795.22 | M49: =IFERROR(K49/J49-1,0) -> 0
A50: 1 | B50: 481 | C50: GRUPO BRAVO NUÑO S.C. DE R.L. DE C.V. | D50: PROAPR | E50: APRORED BOLSA 1KG | F50: 147 | G50: 250 | H50: =G50-F50 -> 103 | I50: =IFERROR(G50/F50-1,0) -> 0.70068027 | J50: 37429.875 | K50: 76281.75 | L50: =K50-J50 -> 38851.875 | M50: =IFERROR(K50/J50-1,0) -> 1.037991
...

Sheet MAYO
C1: CALCULO DE BONOS MAYO
C3: REGION OCCIDENTE
C5: KILOS | E5: Variacion | G5: PESOS | I5: Variacion
B6: MES | C6: Presupuesto | D6: Real | E6: KG | F6: % | G6: Presupuesto | H6: Real | I6: $ | J6: %
B7: MAYO | C7: ='ESSENTIA MAYO'!O30 -> 163628.76 | D7: ='ESSENTIA MAYO'!N30 -> 145456.34 | E7: =D7-C7 -> -18172.42 | F7: =D7/C7-1 -> -0.11105884 | G7: ='ESSENTIA MAYO'!G30 -> 5170577 | H7: ='ESSENTIA MAYO'!F30 -> 4759735 | I7: =H7-G7 -> -410842 | J7: =H7/G7-1 -> -0.079457668
B9: COMPOSICION BONO | G9: ALCANCE DE OBJETIVOS
B10: Bono | C10: Concepto | D10: % Bono | E10: Monto | G10: Concepto | H10: Presupuesto | I10: Real | J10: % Cobertura | K10: Bono | M10: Objetivo Minimo
B11: 12000 | C11: Cumplimiento Presupuesto | D11: 0.7 | E11: =B11*D11 -> 8400 | G11: Cumplimiento Presupuesto | H11: =G7 -> 5170577 | I11: =H7 -> 4759735 | J11: =IFERROR(I11/H11,0) -> 0.92054233 | K11: =IF(J11<M11,0,J11*$E11) -> 7732.5556 | M11: 0.9
C12: Cierre de 3 pedidos 1000 Kgcon clientes actuales de FMC | D12: 0.12 | E12: =B11*D12 -> 1440 | G12: =C12 -> Cierre de 3 pedidos 1000 Kgcon clientes actuales de FMC | H12: 1 | J12: =I12/H12 -> 0 | K12: =IF(J12<M12,0,J12*$E12) -> 0 | M12: 0.8
C13: Contar con calendario de pruebas inicios de año 2020 | D13: 0.05 | E13: =B$11*D$13 -> 600 | G13: =C13 -> Contar con calendario de pruebas inicios de año 2020 | H13: 1 | J13: =I13/H13 -> 0 | K13: =IF(J13<M13,0,J13*$E13) -> 0 | M13: 1
C14: Presentar estrategica por region Occidente 2020 | D14: 0.05 | E14: =B$11*D$13 -> 600 | G14: =C14 -> Presentar estrategica por region Occidente 2020 | H14: 1 | J14: =I14/H14 -> 0 | K14: =IF(J14<M14,0,J14*$E14) -> 0 | M14: 0.75
C15: Presentar presupuesto lunes 6 de Diciembre | D15: 0.08 | E15: =B11*D15 -> 960 | G15: =C15 -> Presentar presupuesto lunes 6 de Diciembre | H15: 1 | J15: =I15/H15 -> 0 | K15: =IF(J15<M15,0,J15*$E15) -> 0 | M15: 0.75
C16: Total | D16: =SUM(D11:D15) -> 1 | E16: =SUM(E11:E15) -> 12000 | J16: Total sin Presupuesto | K16: =SUM(K12:K15) -> 0
J18: TOTAL | K18: =+K16+K11 -> 7732.5556
C24: REGION PACIFICO
C26: KILOS | E26: Variacion | G26: PESOS | I26: Variacion
B27: MES | C27: Presupuesto | D27: Real | E27: KG | F27: % | G27: Presupuesto | H27: Real | I27: $ | J27: %
B28: =$B$7 -> MAYO | C28: ='ESSENTIA MAYO'!O31 -> 36553 | D28: ='ESSENTIA MAYO'!N31 -> 23178.992 | E28: =D28-C28 -> -13374.008 | F28: =D28/C28-1 -> -0.3658799 | G28: ='ESSENTIA MAYO'!G31 -> 2421147.9 | H28: ='ESSENTIA MAYO'!F31 -> 1727675.3 | I28: =H28-G28 -> -693472.62 | J28: =H28/G28-1 -> -0.28642308
B30: COMPOSICION BONO
B31: Bono | C31: Concepto | D31: % Bono | E31: Monto | F31: Objetivo Minimo | G31: Concepto | H31: Presupuesto | I31: Real | J31: % Cobertura | K31: Bono | M31: Objetivo Minimo
B32: 1000 | C32: Cumplimiento Presupuesto | D32: =E32/$B$37 -> 0.15384615 | E32: 1000 | F32: 0.5 | G32: =C32 -> Cumplimiento Presupuesto | H32: =G28 -> 2421147.9 | I32: =H28 -> 1727675.3 | J32: =IFERROR(I32/H32,0) -> 0.71357692 | K32: =IF(J32<M32,0,J32*$E32) -> 713.57692 | M32: 0.5
B33: 1000 | C33: Pruebas atorizadas por realizar con cliente | D33: =E33/$B$37 -> 0.15384615 | E33: 1000 | F33: 1 | G33: =C33 -> Pruebas atorizadas por realizar con cliente | H33: 1 | J33: =IFERROR(I33/H33,0) -> 0 | K33: =IF(J33<M33,0,J33*$E33) -> 0 | M33: 1
B34: 1500 | C34: Armado e implementación estrategia Baja California | D34: =E34/$B$37 -> 0.23076923 | E34: 1500 | F34: 1 | G34: =C34 -> Armado e implementación estrategia Baja California | H34: 1 | J34: =IFERROR(I34/H34,0) -> 0 | K34: =IF(J34<M34,0,J34*$E34) -> 0 | M34: 1
B35: 1500 | C35: Presentar estrategica por región 2020 | D35: =E35/$B$37 -> 0.23076923 | E35: 1500 | F35: 0.75 | G35: =C35 -> Presentar estrategica por región 2020 | H35: 1 | J35: =IFERROR(I35/H35,0) -> 0 | K35: =IF(J35<M35,0,J35*$E35) -> 0 | M35: 0.75
B36: 1500 | C36: Presentar presupuesto lunes 6 de Diciembre | D36: =E36/$B$37 -> 0.23076923 | E36: 1500 | F36: 0.75 | G36: =C36 -> Presentar presupuesto lunes 6 de Diciembre | H36: 1 | J36: =IFERROR(I36/H36,0) -> 0 | K36: =IF(J36<M36,0,J36*$E36) -> 0 | M36: 0.75
B37: =SUM(B32:B36) -> 6500 | C37: Total | E37: =SUM(E31:E36) -> 6500 | J37: Total sin Presupuesto | K37: =SUM(K34:K34) -> 0
J39: TOTAL | K39: =+K37+K32 -> 713.57692
C43: REGION BAJIO
C45: KILOS | E45: Variacion | G45: PESOS | I45: Variacion
B46: MES | C46: Presupuesto | D46: Real | E46: KG | F46: % | G46: Presupuesto | H46: Real | I46: $ | J46: %
B47: =$B$7 -> MAYO | C47: ='ESSENTIA MAYO'!O36 -> 28902.142 | D47: ='ESSENTIA MAYO'!N36 -> 26639.24 | E47: =D47-C47 -> -2262.902 | F47: =D47/C47-1 -> -0.078295304 | G47: ='ESSENTIA MAYO'!G36 -> 1694685.6 | H47: ='ESSENTIA MAYO'!F36 -> 1452368.4 | I47: =H47-G47 -> -242317.2 | J47: =H47/G47-1 -> -0.14298652
B49: COMPOSICION BONO | G49: ALCANCE DE OBJETIVOS
B50: Bono | C50: Concepto | D50: % Bono | E50: Monto | G50: Concepto | H50: Presupuesto | I50: Real | J50: % Cobertura | K50: Bono
B51: 7000 | C51: Cumplimiento Presupuesto | D51: 0.5 | E51: =B51*D51 -> 3500 | G51: =C51 -> Cumplimiento Presupuesto | H51: =G47 -> 1694685.6 | I51: =H47 -> 1452368.4 | J51: =IFERROR(I51/H51,0) -> 0.85701348 | K51: =IF(J51<M52,0,J51*$E51) -> 0 | M51: Objetivo Minimo
C52: Aplicación de pruebas unidades de chorizo | D52: 0.2 | E52: =B51*D52 -> 1400 | G52: =C52 -> Aplicación de pruebas unidades de chorizo | H52: 1 | J52: =IFERROR(I52/H52,0) -> 0 | K52: =IF(J52<M53,0,J52*$E52) -> 0 | M52: 0.95
C53: Prospectación | D53: 0.2 | E53: =B51*D53 -> 1400 | G53: =C53 -> Prospectación | H53: 1 | J53: =IFERROR(I53/H53,0) -> 0 | K53: =IF(J53<M54,0,J53*$E53) -> 0 | M53: 0.75
C54: Cierre de venta con productos nuevos AGR | D54: 0.1 | E54: =+D54*B51 -> 700 | G54: =C54 -> Cierre de venta con productos nuevos AGR | H54: 1 | J54: =IFERROR(I54/H54,0) -> 0 | K54: =IF(J54<M55,0,J54*$E54) -> 0 | M54: 0.75
C55: Total | D55: =SUM(D51:D54) -> 1 | E55: =SUM(E51:E54) -> 7000 | J55: Total sin Presupuesto | K55: =SUM(K52:K54) -> 0 | M55: 0.75
J57: TOTAL | K57: =+K55+K51 -> 0
C61: ALTOS NORTE
...

Sheet ESSENTIA MAYO
E3: PRESUPUESTO ORIGINAL | F3: Importes | N3: Kilogramos
D4: Clave | E4: Region | F4: 2020 | G4: Pres | H4: Dif | I4: % Inc | J4: 2019 | K4: Dif | L4: % Inc | N4: 2020 | O4: Pres | P4: Dif | Q4: % Inc | R4: 2019 | S4: Dif | T4: % Inc
